<?xml version="1.0" ?>
<robot xmlns:xacro="http://www.ros.org/wiki/xacro">

  <xacro:include filename="base.urdf.xacro"/>
  <xacro:include filename="left_middle_arm.urdf.xacro"/>
  <xacro:include filename="left_front_arm.urdf.xacro"/>
  <xacro:include filename="left_back_arm.urdf.xacro"/>
  <xacro:include filename="right_middle_arm.urdf.xacro"/>
  <xacro:include filename="right_front_arm.urdf.xacro"/>
  <xacro:include filename="right_back_arm.urdf.xacro"/>
  <xacro:include filename="wheel_steering.urdf.xacro"/>
  <xacro:include filename="wheel.urdf.xacro"/>

  <link name="base_link"/>

  <xacro:base name="base" parent="base_link">
    <origin xyz="0 0 0.355" rpy="0 0 ${pi/2}"/> <!-- wheels touch the ground with z=0.345-->
  </xacro:base>

  <!-- Add joints and links to simulation differential-like gears -->
  <!-- This is made in order to make the rotation of the shoulders to be the oposite to one another-->

  <joint name="shoulder_joint" type="continuous">
    <parent link="base"/>
    <child link="shoulder"/>
    <origin xyz="0 ${-0.225} 0"/>
    <axis xyz="0 1 0"/>
  </joint>

  <link name="shoulder">
  </link>

  <joint name="shoulder_left_joint" type="continuous">
    <parent link="base"/>
    <child link="shoulder_left"/>
    <origin xyz="${0.255/2 + 0.05} ${0.045-0.225} 0"/>
    <axis xyz="1 0 0"/>
    <mimic joint="shoulder_joint" multiplier="1"/>
  </joint>

  <link name="shoulder_left">
  </link>

  <joint name="shoulder_right_joint" type="continuous">
    <parent link="base"/>
    <child link="shoulder_right"/>
    <origin xyz="${-0.255/2 - 0.05} ${0.045-0.225} 0"/>
    <axis xyz="1 0 0"/>
    <mimic joint="shoulder_joint" multiplier="-1"/>
  </joint>

  <link name="shoulder_right">
  </link>
  <!-- End of differential-like gears -->

  <xacro:left_middle_arm name="left_middle_arm" parent="shoulder_left">
    <origin xyz="0 0 0" rpy="0 ${pi/2} 0"/>
  </xacro:left_middle_arm>

  <xacro:left_front_arm name="left_front_arm" parent="left_middle_arm">
    <origin xyz="${0.045/2 + 0.11 - 0.07/2} 0 0" rpy="0 0 0"/>
  </xacro:left_front_arm>

  <xacro:wheel_steering name="left_front_wheel" parent="left_front_arm">
    <origin xyz="0 ${-0.07-0.18-0.015} ${-0.15}" rpy="${pi} 0 0"/>
  </xacro:wheel_steering>

  <xacro:left_back_arm name="left_back_arm" parent="left_middle_arm">
    <origin xyz="${0.045/2 + 0.11 - 0.07/2} ${0.18 + 0.2} ${-0.075}" rpy="0 0 0"/>
  </xacro:left_back_arm>

  <xacro:wheel_steering name="left_middle_wheel" parent="left_back_arm">
    <origin xyz="0 ${-0.045 - 0.1 - 0.14/2} ${-0.075}" rpy="${pi} 0 0"/>
  </xacro:wheel_steering>

  <xacro:wheel_steering name="left_back_wheel" parent="left_back_arm">
    <origin xyz="0 ${0.045 + 0.1 + 0.14/2} ${-0.075}" rpy="${pi} 0 0"/>
  </xacro:wheel_steering>

  <xacro:right_middle_arm name="right_middle_arm" parent="shoulder_right">
    <origin xyz="0 0 0" rpy="0 ${pi/2} 0"/>
  </xacro:right_middle_arm>

  <xacro:right_front_arm name="right_front_arm" parent="right_middle_arm">
    <origin xyz="${-0.045/2 - 0.11 + 0.07/2} 0 0" rpy="0 0 0"/>
  </xacro:right_front_arm>

  <xacro:wheel_steering name="right_front_wheel" parent="right_front_arm">
    <origin xyz="0 ${-0.07-0.18-0.015} ${-0.15}" rpy="${pi} 0 0"/>
  </xacro:wheel_steering>

  <xacro:wheel_steering name="right_middle_wheel" parent="right_back_arm">
    <origin xyz="0 ${-0.045 - 0.1 - 0.14/2} ${-0.075}" rpy="${pi} 0 0"/>
  </xacro:wheel_steering>

  <xacro:wheel_steering name="right_back_wheel" parent="right_back_arm">
    <origin xyz="0 ${0.045 + 0.1 + 0.14/2} ${-0.075}" rpy="${pi} 0 0"/>
  </xacro:wheel_steering>

  <xacro:right_back_arm name="right_back_arm" parent="right_middle_arm">
    <origin xyz="${-0.045/2 - 0.11 + 0.07/2} ${0.18 + 0.2} ${-0.075}" rpy="0 0 0"/>
  </xacro:right_back_arm>

</robot>
