<?xml version="1.0" ?>
<robot xmlns:xacro="http://www.ros.org/wiki/xacro">

  <xacro:include filename="inertial_macros.urdf.xacro"/>

	<xacro:arg name="ignition" default="false"/>

	<xacro:macro name="wheel" params="name parent *origin">

    <joint name="${name}_joint" type="continuous">
			<parent link="${parent}"/>
			<child link="${name}_axis"/>
			<xacro:insert_block name="origin"/>
			<axis xyz="0 0 1"/>
      <limit effort="${13.3*9.81*2.9}" velocity="${1000*2*pi/60}"/> <!-- TODO replace with motor limits -->
      <!-- <dynamics damping="0.1" friction="1"/> -->
      <!-- TODO replace with motor + axis properties-->
		</joint>

		<link name="${name}_axis">
			<visual>
				<geometry>
					<mesh filename="package://forg_description/meshes/wheel_axis.dae"/>
				</geometry>
			</visual>
			<collision>
				<geometry>
					<mesh filename="package://forg_description/meshes/wheel_axis.dae"/>
				</geometry>
			</collision>
      <xacro:inertial_cylinder mass="0.05" length="0.17" radius="0.00625"/> <!-- TODO replace wheel axis mass with real value -->
		</link>

    <joint name="${name}_axis_joint" type="fixed">
			<parent link="${name}_axis"/>
			<child link="${name}"/>
      <origin rpy="0 ${-pi/2} 0"/>
			<axis xyz="1 0 0"/>
		</joint>

		<link name="${name}">
			<visual>
				<geometry>
					<mesh filename="package://forg_description/meshes/wheel.dae"/>
				</geometry>
			</visual>
			<collision>
				<geometry>
					<mesh filename="package://forg_description/meshes/wheel.dae"/>
				</geometry>
			</collision>
      <xacro:inertial_cylinder mass="0.2" length="0.015" radius="0.06"/> <!-- TODO replace wheel mass with real value -->
		</link>

	</xacro:macro>
</robot>
